Traceback (most recent call last):
  File "/usr/local/lib/python3.9/dist-packages/jupyter_cache/executors/utils.py", line 58, in single_nb_execution
    executenb(
  File "/usr/local/lib/python3.9/dist-packages/nbclient/client.py", line 1204, in execute
    return NotebookClient(nb=nb, resources=resources, km=km, **kwargs).execute()
  File "/usr/local/lib/python3.9/dist-packages/nbclient/util.py", line 84, in wrapped
    return just_run(coro(*args, **kwargs))
  File "/usr/local/lib/python3.9/dist-packages/nbclient/util.py", line 62, in just_run
    return loop.run_until_complete(coro)
  File "/usr/lib/python3.9/asyncio/base_events.py", line 647, in run_until_complete
    return future.result()
  File "/usr/local/lib/python3.9/dist-packages/nbclient/client.py", line 663, in async_execute
    await self.async_execute_cell(
  File "/usr/local/lib/python3.9/dist-packages/nbclient/client.py", line 965, in async_execute_cell
    await self._check_raise_for_error(cell, cell_index, exec_reply)
  File "/usr/local/lib/python3.9/dist-packages/nbclient/client.py", line 862, in _check_raise_for_error
    raise CellExecutionError.from_cell_and_msg(cell, exec_reply_content)
nbclient.exceptions.CellExecutionError: An error occurred while executing the following cell:
------------------
data_gaji = df[["gaji"]]
data_gaji
------------------

[0;31m[0m
[0;31mKeyError[0mTraceback (most recent call last)
[0;32m<ipython-input-5-1413ebcad786>[0m in [0;36m<cell line: 1>[0;34m()[0m
[0;32m----> 1[0;31m [0mdata_gaji[0m [0;34m=[0m [0mdf[0m[0;34m[[0m[0;34m[[0m[0;34m"gaji"[0m[0;34m][0m[0;34m][0m[0;34m[0m[0;34m[0m[0m
[0m[1;32m      2[0m [0mdata_gaji[0m[0;34m[0m[0;34m[0m[0m

[0;32m/usr/local/lib/python3.9/dist-packages/pandas/core/frame.py[0m in [0;36m__getitem__[0;34m(self, key)[0m
[1;32m   3509[0m             [0;32mif[0m [0mis_iterator[0m[0;34m([0m[0mkey[0m[0;34m)[0m[0;34m:[0m[0;34m[0m[0;34m[0m[0m
[1;32m   3510[0m                 [0mkey[0m [0;34m=[0m [0mlist[0m[0;34m([0m[0mkey[0m[0;34m)[0m[0;34m[0m[0;34m[0m[0m
[0;32m-> 3511[0;31m             [0mindexer[0m [0;34m=[0m [0mself[0m[0;34m.[0m[0mcolumns[0m[0;34m.[0m[0m_get_indexer_strict[0m[0;34m([0m[0mkey[0m[0;34m,[0m [0;34m"columns"[0m[0;34m)[0m[0;34m[[0m[0;36m1[0m[0;34m][0m[0;34m[0m[0;34m[0m[0m
[0m[1;32m   3512[0m [0;34m[0m[0m
[1;32m   3513[0m         [0;31m# take() does not accept boolean indexers[0m[0;34m[0m[0;34m[0m[0m

[0;32m/usr/local/lib/python3.9/dist-packages/pandas/core/indexes/base.py[0m in [0;36m_get_indexer_strict[0;34m(self, key, axis_name)[0m
[1;32m   5794[0m             [0mkeyarr[0m[0;34m,[0m [0mindexer[0m[0;34m,[0m [0mnew_indexer[0m [0;34m=[0m [0mself[0m[0;34m.[0m[0m_reindex_non_unique[0m[0;34m([0m[0mkeyarr[0m[0;34m)[0m[0;34m[0m[0;34m[0m[0m
[1;32m   5795[0m [0;34m[0m[0m
[0;32m-> 5796[0;31m         [0mself[0m[0;34m.[0m[0m_raise_if_missing[0m[0;34m([0m[0mkeyarr[0m[0;34m,[0m [0mindexer[0m[0;34m,[0m [0maxis_name[0m[0;34m)[0m[0;34m[0m[0;34m[0m[0m
[0m[1;32m   5797[0m [0;34m[0m[0m
[1;32m   5798[0m         [0mkeyarr[0m [0;34m=[0m [0mself[0m[0;34m.[0m[0mtake[0m[0;34m([0m[0mindexer[0m[0;34m)[0m[0;34m[0m[0;34m[0m[0m

[0;32m/usr/local/lib/python3.9/dist-packages/pandas/core/indexes/base.py[0m in [0;36m_raise_if_missing[0;34m(self, key, indexer, axis_name)[0m
[1;32m   5854[0m                 [0;32mif[0m [0muse_interval_msg[0m[0;34m:[0m[0;34m[0m[0;34m[0m[0m
[1;32m   5855[0m                     [0mkey[0m [0;34m=[0m [0mlist[0m[0;34m([0m[0mkey[0m[0;34m)[0m[0;34m[0m[0;34m[0m[0m
[0;32m-> 5856[0;31m                 [0;32mraise[0m [0mKeyError[0m[0;34m([0m[0;34mf"None of [{key}] are in the [{axis_name}]"[0m[0;34m)[0m[0;34m[0m[0;34m[0m[0m
[0m[1;32m   5857[0m [0;34m[0m[0m
[1;32m   5858[0m             [0mnot_found[0m [0;34m=[0m [0mlist[0m[0;34m([0m[0mensure_index[0m[0;34m([0m[0mkey[0m[0;34m)[0m[0;34m[[0m[0mmissing_mask[0m[0;34m.[0m[0mnonzero[0m[0;34m([0m[0;34m)[0m[0;34m[[0m[0;36m0[0m[0;34m][0m[0;34m][0m[0;34m.[0m[0munique[0m[0;34m([0m[0;34m)[0m[0;34m)[0m[0;34m[0m[0;34m[0m[0m

[0;31mKeyError[0m: "None of [Index(['gaji'], dtype='object')] are in the [columns]"
KeyError: "None of [Index(['gaji'], dtype='object')] are in the [columns]"

